<?xml version="1.0"?>
<robot xmlns:xacro="http://ros.org/wiki/xacro">

  <xacro:include filename="$(find plat)/urdf/common.xacro"/>
  <xacro:include filename="$(find plat)/urdf/wheel/wheel.transmission.xacro"/>
  <xacro:include filename="$(find plat)/urdf/wheel/wheel.gazebo.xacro"/>

  <property name="wheel_radius" value="0.1"/>
  <property name="wheel_length" value="0.055"/>
  <property name="wheel_mass" value="1.5"/>
  
  <xacro:macro name="wheel_v0" params="prefix parent *joint_origin *joint_axis">
	<joint name="${prefix}_wheel_joint" type="continuous">
	  <insert_block name="joint_origin"/>
	  <parent link="${parent}"/>
	  <child link="${prefix}_wheel_link"/>
	  <insert_block name="joint_axis"/>
	</joint>

	<link name="${prefix}_wheel_link">
	  <visual>
		<geometry>
		  <!--<mesh filename="package://kcctsim/meshes/DAE/wheel/wheel_link.dae"/>-->
		   <mesh filename="package://plat/meshes/STL/wheel/plat_wheel.stl" scale="0.001 0.001 0.001"/>
		</geometry>
		<material name="black">
    		<color rgba="0.2 0.2 0.2 2.0"/>
  		</material>
	  </visual>
	  <collision>
		<origin xyz="0 0 0" rpy="${-M_PI/2} 0 0"/>
		<geometry>
		  <cylinder radius="${wheel_radius}" length="${wheel_length}"/>
		</geometry>
	  </collision>
	  <inertial>
		<origin xyz="0 0 0" rpy="${-M_PI/2} 0 0"/>
		<cylinder_inertial mass="${wheel_mass}"
						   radius="${wheel_radius}" length="${wheel_length}"/>
	  </inertial>
	</link>
  </xacro:macro>
  
</robot>
